Workbook

Sheet IDs
A1: id | B1: mun | C1: mun_ar | D1: city
A2: 1 | B2: Aarab Sebbah Gheris | C2: اعرب صباح اغريس | D2: Casablanca | E2: Sidi Moumen | F2: سيدي مومن
A3: 2 | B3: Aarab Sebbah Ziz | C3: عرب صباح زيز | E3: Hay-Hassani | F3: الحي الحسني
A4: 3 | B4: Abadou | C4: أبادو | E4: Aïn-Chock | F4: عين الشق
A5: 4 | B5: Abaynou | C5: أباينو | E5: Moulay Rachid | F5: مولاي رشيد
A6: 5 | B6: Abbou Lakhal | C6: عبو لكحل | E6: Sidi Othmane | F6: سيدي عثمان
A7: 6 | B7: Abdelghaya Souahel | C7: عبد الغاية السواحل | E7: Sidi Bernoussi | F7: سيدي البرنوصي
A8: 7 | B8: Abteh | C8: أبطيح | E8: Aïn-Sebaâ | F8: عين السبع
A9: 8 | B9: Adaghas | C9: أدغاس | E9: Maârif | F9: المعاريف
A10: 9 | B10: Adar | C10: أضار | E10: Sidi Belyout | F10: سيدي بليوط
A11: 10 | B11: Adassil | C11: اداسيل | E11: Al-Fida | F11: الفداء
A12: 11 | B12: Aday | C12: أداي | E12: Ben-M'sick | F12: ابن مسيك
A13: 12 | B13: Adis | C13: اديس | E13: Asoukhour Assawda | F13: الصخور السوداء
A14: 13 | B14: Adrej | C14: أدرج | E14: Hay-Mohammadi | F14: الحي المحمدي
... A16: 15 | B16: Afella Ighir | C16: أفلا إغير | E16: Mers-Sultan | F16: مرس السلطان
A17: 16 | B17: Afella N'dra | C17: أفلاندرا | E17: Anfa | F17: أنفا | G17: Oulad Azzouz
A18: 17 | B18: Aferkat | C18: افركط | E18: Dar Bouazza | F18: دار بوعزة
A19: 18 | B19: Afourar | C19: أفورار | E19: Bouskoura | F19: بوسكورة
A20: 19 | B20: Afra | C20: أفرا | E20: Oulad Azzouz | F20: أولاد عزوز
A21: 20 | B21: Afsou | C21: افسو | E21: Ouled Salah | F21: أولاد صالح
A22: 21 | B22: Agadir | C22: أكادير | E22: Nouaceur | F22: النواصر
A23: 22 | B23: Agadir Melloul | C23: أكادير ملول
A24: 23 | B24: Agafay | C24: أكفاي
A25: 24 | B25: Agdal | C25: أكدال
A26: 25 | B26: Agdal Riyad | C26: أكدال الرياض
A27: 26 | B27: Agdz | C27: أكدز
A28: 27 | B28: Aghbal | C28: أغبال
A29: 28 | B29: Aghbala | C29: اغبالة
A30: 29 | B30: Aghbalou | C30: أغبالو
A31: 30 | B31: Aghbalou Aqorar | C31: اغبالو أقورار
A32: 31 | B32: Aghbalou-N'kerdous | C32: اغبالو انكردوس
A33: 32 | B33: Aghbar | C33: اغبار
A34: 33 | B34: Aghouatim | C34: اغواطيم
... A1540: 1539 | B1540: Zrizer | C1540: الزريزر

Sheet mun_pop
A1: mun_id | B1: mun | C1: city | D1: pop_total | E1: pop_total_male | F1: pop_total_female | G1: pop_under_15 | H1: pop_under_15_male | I1: pop_under_15_female | J1: pop_15_59 | K1: pop_15_59_male | L1: pop_15_59_female | M1: pop_60 | N1: pop_60_male | O1: pop_60_female
A2: {=INDEX(IDs!A:A, MATCH(B2, IDs!B:B, 0))} -> 1 | B2: Aarab Sebbah Gheris | D2: 4758 | E2: 2444 | F2: 2314 | G2: 33.2 | H2: 34.6 | I2: 31.8 | J2: 55 | K2: 53.8 | L2: 56.2 | M2: 11.8 | N2: 11.6 | O2: 12.1
A3: {=INDEX(IDs!A:A, MATCH(B3, IDs!B:B, 0))} -> 2 | B3: Aarab Sebbah Ziz | D3: 20538 | E3: 10547 | F3: 9991 | G3: 32.2 | H3: 32.7 | I3: 31.7 | J3: 57.1 | K3: 56.4 | L3: 57.7 | M3: 10.7 | N3: 10.9 | O3: 10.5
A4: {=INDEX(IDs!A:A, MATCH(B4, IDs!B:B, 0))} -> 3 | B4: Abadou | D4: 10482 | E4: 5594 | F4: 4888 | G4: 27.4 | H4: 27.3 | I4: 27.6 | J4: 58.4 | K4: 58.8 | L4: 57.9 | M4: 14.2 | N4: 13.8 | O4: 14.5
A5: {=INDEX(IDs!A:A, MATCH(B5, IDs!B:B, 0))} -> 4 | B5: Abaynou | D5: 2932 | E5: 1428 | F5: 1504 | G5: 30.1 | H5: 29.3 | I5: 30.9 | J5: 55.9 | K5: 57.1 | L5: 54.7 | M5: 14.1 | N5: 13.6 | O5: 14.5
A6: {=INDEX(IDs!A:A, MATCH(B6, IDs!B:B, 0))} -> 5 | B6: Abbou Lakhal | D6: 1789 | E6: 901 | F6: 888 | G6: 39.6 | H6: 38.6 | I6: 40.5 | J6: 53 | K6: 53.3 | L6: 52.7 | M6: 7.4 | N6: 8.1 | O6: 6.8
A7: {=INDEX(IDs!A:A, MATCH(B7, IDs!B:B, 0))} -> 6 | B7: Abdelghaya Souahel | D7: 24435 | E7: 13191 | F7: 11244 | G7: 28.9 | H7: 27.9 | I7: 30 | J7: 60.9 | K7: 63.3 | L7: 58 | M7: 10.3 | N7: 8.8 | O7: 12
A8: {=INDEX(IDs!A:A, MATCH(B8, IDs!B:B, 0))} -> 7 | B8: Abteh | D8: 647 | E8: 329 | F8: 318 | G8: 24.6 | H8: 25.5 | I8: 23.6 | J8: 65.4 | K8: 64.4 | L8: 66.4 | M8: 10 | N8: 10 | O8: 10.1
A9: {=INDEX(IDs!A:A, MATCH(B9, IDs!B:B, 0))} -> 8 | B9: Adaghas | D9: 1656 | E9: 838 | F9: 818 | G9: 27.1 | H9: 29.2 | I9: 24.8 | J9: 50.4 | K9: 48.7 | L9: 52.1 | M9: 22.6 | N9: 22.1 | O9: 23.1
A10: {=INDEX(IDs!A:A, MATCH(B10, IDs!B:B, 0))} -> 9 | B10: Adar | D10: 3038 | E10: 1152 | F10: 1886 | G10: 20 | H10: 27.4 | I10: 15.5 | J10: 49.8 | K10: 39 | L10: 56.4 | M10: 30.2 | N10: 33.6 | O10: 28
A11: {=INDEX(IDs!A:A, MATCH(B11, IDs!B:B, 0))} -> 10 | B11: Adassil | D11: 7059 | E11: 3681 | F11: 3378 | G11: 30.2 | H11: 30 | I11: 30.4 | J11: 56 | K11: 56.1 | L11: 55.8 | M11: 13.8 | N11: 13.9 | O11: 13.8
A12: {=INDEX(IDs!A:A, MATCH(B12, IDs!B:B, 0))} -> 11 | B12: Aday | D12: 2825 | E12: 1317 | F12: 1508 | G12: 25 | H12: 27.9 | I12: 22.3 | J12: 54.5 | K12: 52.2 | L12: 56.5 | M12: 20.6 | N12: 19.9 | O12: 21.2
A13: {=INDEX(IDs!A:A, MATCH(B13, IDs!B:B, 0))} -> 12 | B13: Adis | D13: 6227 | E13: 2925 | F13: 3302 | G13: 25.7 | H13: 29.1 | I13: 22.6 | J13: 58.2 | K13: 57.2 | L13: 59.2 | M13: 16.1 | N13: 13.7 | O13: 18.2
... A34: {=INDEX(IDs!A:A, MATCH(B34, IDs!B:B, 0))} -> 33 | B34: Aghouatim | D34: 36090 | E34: 18960 | F34: 17130 | G34: 30 | H34: 29.9 | I34: 30.1 | J34: 58.2 | K34: 58.4 | L34: 58 | M34: 11.8 | N34: 11.7 | O34: 11.9
A35: {=INDEX(IDs!A:A, MATCH(B35, IDs!B:B, 0))} -> 34 | B35: Aghouinite-N/A | D35: 1006 | E35: N/A | F35: N/A | G35: N/A | H35: N/A | I35: N/A | J35: N/A | K35: N/A | L35: N/A | M35: N/A | N35: N/A | O35: N/A
A36: {=INDEX(IDs!A:A, MATCH(B36, IDs!B:B, 0))} -> 35 | B36: Aglif | D36: 6499 | E36: 3160 | F36: 3339 | G36: 31.4 | H36: 33.5 | I36: 29.4 | J36: 48.9 | K36: 47.3 | L36: 50.4 | M36: 19.7 | N36: 19.2 | O36: 20.2
A37: {=INDEX(IDs!A:A, MATCH(B37, IDs!B:B, 0))} -> 36 | B37: Agoudi N'lkhair | D37: 11963 | E37: 6173 | F37: 5790 | G37: 31.5 | H37: 31.2 | I37: 31.8 | J37: 56.4 | K37: 57.3 | L37: 55.5 | M37: 12.1 | N37: 11.5 | O37: 12.7
A38: {=INDEX(IDs!A:A, MATCH(B38, IDs!B:B, 0))} -> 37 | B38: Agoudim | D38: 3822 | E38: 1966 | F38: 1856 | G38: 28.9 | H38: 28.7 | I38: 29 | J38: 55.7 | K38: 56.6 | L38: 54.8 | M38: 15.4 | N38: 14.7 | O38: 16.2
A39: {=INDEX(IDs!A:A, MATCH(B39, IDs!B:B, 0))} -> 38 | B39: Agourai | D39: 19158 | E39: 9486 | F39: 9672 | G39: 26.8 | H39: 28.4 | I39: 25.2 | J39: 59.2 | K39: 58.1 | L39: 60.3 | M39: 14 | N39: 13.5 | O39: 14.5
A40: {=INDEX(IDs!A:A, MATCH(B40, IDs!B:B, 0))} -> 39 | B40: Aguelmam Azegza | D40: 6779 | E40: 3504 | F40: 3275 | G40: 25.7 | H40: 25.4 | I40: 26 | J40: 57.7 | K40: 58.1 | L40: 57.3 | M40: 16.6 | N40: 16.4 | O40: 16.7
A41: {=INDEX(IDs!A:A, MATCH(B41, IDs!B:B, 0))} -> 40 | B41: Aguelmous | D41: 36555 | E41: 18500 | F41: 18055 | G41: 25.3 | H41: 26.1 | I41: 24.6 | J41: 60 | K41: 59.7 | L41: 60.4 | M41: 14.6 | N41: 14.2 | O41: 15
A42: {=INDEX(IDs!A:A, MATCH(B42, IDs!B:B, 0))} -> 41 | B42: Aguerd | D42: 5370 | E42: 2714 | F42: 2656 | G42: 26.1 | H42: 26.1 | I42: 26.1 | J42: 55.4 | K42: 54.9 | L42: 55.8 | M42: 18.5 | N42: 19 | O42: 18
A43: {=INDEX(IDs!A:A, MATCH(B43, IDs!B:B, 0))} -> 42 | B43: Aguinane | D43: 2396 | E43: 1079 | F43: 1317 | G43: 24 | H43: 25.7 | I43: 22.6 | J43: 53 | K43: 50.7 | L43: 54.8 | M43: 23.1 | N43: 23.6 | O43: 22.6
A44: {=INDEX(IDs!A:A, MATCH(B44, IDs!B:B, 0))} -> 43 | B44: Ahdil | D44: 11130 | E44: 5988 | F44: 5142 | G44: 32.6 | H44: 30.9 | I44: 34.6 | J44: 56.2 | K44: 58 | L44: 54.1 | M44: 11.2 | N44: 11.1 | O44: 11.3
A45: {=INDEX(IDs!A:A, MATCH(B45, IDs!B:B, 0))} -> 44 | B45: Ahfir | D45: 15857 | E45: 7408 | F45: 8449 | G45: 18.1 | H45: 19.2 | I45: 17.3 | J45: 55.6 | K45: 54.5 | L45: 56.5 | M45: 26.3 | N45: 26.3 | O45: 26.3
A46: {=INDEX(IDs!A:A, MATCH(B46, IDs!B:B, 0))} -> 45 | B46: Ahl Angad | D46: 17943 | E46: 9256 | F46: 8687 | G46: 27.4 | H46: 28 | I46: 26.8 | J46: 59.1 | K46: 58.4 | L46: 59.8 | M46: 13.5 | N46: 13.6 | O46: 13.4
A47: {=INDEX(IDs!A:A, MATCH(B47, IDs!B:B, 0))} -> 46 | B47: Ahl Oued Za | D47: 10672 | E47: 5315 | F47: 5357 | G47: 26.5 | H47: 27.9 | I47: 25.1 | J47: 58.4 | K47: 56.8 | L47: 60.1 | M47: 15.1 | N47: 15.3 | O47: 14.9
... A87: {=INDEX(IDs!A:A, MATCH(B87, IDs!B:B, 0))} -> 86 | B87: Ain Zohra | D87: 8704 | E87: 3915 | F87: 4789 | G87: 27.4 | H87: 29.7 | I87: 25.4 | J87: 56.1 | K87: 54.6 | L87: 57.3 | M87: 16.6 | N87: 15.7 | O87: 17.3
A88: {=INDEX(IDs!A:A, MATCH(B88, IDs!B:B, 0))} -> 87 | B88: Aïn-Chock | C88: Casablanca | D88: 374579 | E88: 184704 | F88: 189875 | G88: 21.2 | H88: 22.3 | I88: 20.2 | J88: 62.3 | K88: 61.7 | L88: 63 | M88: 16.4 | N88: 16.1 | O88: 16.8
A89: {=INDEX(IDs!A:A, MATCH(B89, IDs!B:B, 0))} -> 88 | B89: Aïn-Sebaâ | C89: Casablanca | D89: 143697 | E89: 70042 | F89: 73655 | G89: 21.1 | H89: 22.4 | I89: 19.8 | J89: 61.9 | K89: 61.2 | L89: 62.5 | M89: 17 | N89: 16.4 | O89: 17.6
A90: {=INDEX(IDs!A:A, MATCH(B90, IDs!B:B, 0))} -> 89 | B90: Ait Aadel | D90: 8724 | E90: 4666 | F90: 4058 | G90: 33.1 | H90: 32.1 | I90: 34.2 | J90: 57.2 | K90: 58.3 | L90: 55.8 | M90: 9.8 | N90: 9.6 | O90: 10
A91: {=INDEX(IDs!A:A, MATCH(B91, IDs!B:B, 0))} -> 90 | B91: Ait Abbas | D91: 13541 | E91: 7115 | F91: 6426 | G91: 36.8 | H91: 36.9 | I91: 36.7 | J91: 54.9 | K91: 54.7 | L91: 55.1 | M91: 8.3 | N91: 8.4 | O91: 8.2
A92: {=INDEX(IDs!A:A, MATCH(B92, IDs!B:B, 0))} -> 91 | B92: Ait Abdallah | D92: 1594 | E92: 639 | F92: 955 | G92: 15.9 | H92: 20.7 | I92: 12.7 | J92: 49.7 | K92: 49.8 | L92: 49.7 | M92: 34.4 | N92: 29.6 | O92: 37.6
A93: {=INDEX(IDs!A:A, MATCH(B93, IDs!B:B, 0))} -> 92 | B93: Ait Aissa Ihahane | D93: 2563 | E93: 1179 | F93: 1384 | G93: 23.5 | H93: 24.8 | I93: 22.5 | J93: 49.4 | K93: 47.4 | L93: 51.2 | M93: 27 | N93: 27.8 | O93: 26.4
A94: {=INDEX(IDs!A:A, MATCH(B94, IDs!B:B, 0))} -> 93 | B94: Ait Ali Ou Lahcen | D94: 5139 | E94: 2632 | F94: 2507 | G94: 28.5 | H94: 28.1 | I94: 29 | J94: 58.6 | K94: 59.2 | L94: 58 | M94: 12.9 | N94: 12.7 | O94: 13
A95: {=INDEX(IDs!A:A, MATCH(B95, IDs!B:B, 0))} -> 94 | B95: Ait Amira | D95: 113205 | E95: 58745 | F95: 54460 | G95: 30 | H95: 29.8 | I95: 30.2 | J95: 63.6 | K95: 63.9 | L95: 63.3 | M95: 6.4 | N95: 6.2 | O95: 6.5
A96: {=INDEX(IDs!A:A, MATCH(B96, IDs!B:B, 0))} -> 95 | B96: Ait Ammar | D96: 3392 | E96: 1735 | F96: 1657 | G96: 25.5 | H96: 27.2 | I96: 23.7 | J96: 54.5 | K96: 54 | L96: 55 | M96: 20 | N96: 18.8 | O96: 21.3
A97: {=INDEX(IDs!A:A, MATCH(B97, IDs!B:B, 0))} -> 96 | B97: Ait Ayach | D97: 12932 | E97: 6442 | F97: 6490 | G97: 28.4 | H97: 28.7 | I97: 28.2 | J97: 58.7 | K97: 58.6 | L97: 58.8 | M97: 12.9 | N97: 12.7 | O97: 13.1
A98: {=INDEX(IDs!A:A, MATCH(B98, IDs!B:B, 0))} -> 97 | B98: Ait Baha | D98: 6007 | E98: 3018 | F98: 2989 | G98: 25.7 | H98: 26.9 | I98: 24.4 | J98: 60.7 | K98: 59.6 | L98: 61.8 | M98: 13.6 | N98: 13.5 | O98: 13.8
A99: {=INDEX(IDs!A:A, MATCH(B99, IDs!B:B, 0))} -> 98 | B99: Ait Bazza | D99: 2397 | E99: 1229 | F99: 1168 | G99: 27.1 | H99: 29 | I99: 25.2 | J99: 55.4 | K99: 55.7 | L99: 55.1 | M99: 17.4 | N99: 15.3 | O99: 19.7
...

Sheet marital_status
A1: mun_id | B1: mun | C1: single_p_15 | D1: single_p_15_male | E1: single_p_15_female | F1: married_p_15 | G1: married_p_15_male | H1: married_p_15_female | I1: divorced_p_15 | J1: divorced_p_15_male | K1: divorced_p_15_female | L1: widowed_p_15 | M1: widowed_p_15_male | N1: widowed_p_15_female | O1: avg_age_first_marriage | P1: avg_age_first_marriage_male | Q1: avg_age_first_marriage_female | R1: avg_children_45_49 | S1: total_fertility_rate
A2: {=INDEX(IDs!A:A, MATCH(B2, IDs!B:B, 0))} -> 1 | B2: Aarab Sebbah Gheris | C2: 27.5 | D2: 35.2 | E2: 19.6 | F2: 64.7 | G2: 62.7 | H2: 66.7 | I2: 2.8 | J2: 1.3 | K2: 4.2 | L2: 5.1 | M2: 0.8 | N2: 9.4 | O2: 26.6 | P2: 30.6 | Q2: 22.8 | R2: 4 | S2: 2.71
A3: {=INDEX(IDs!A:A, MATCH(B3, IDs!B:B, 0))} -> 2 | B3: Aarab Sebbah Ziz | C3: 28.6 | D3: 34.7 | E3: 22.2 | F3: 63.6 | G3: 63 | H3: 64.2 | I3: 3.1 | J3: 1.5 | K3: 4.7 | L3: 4.7 | M3: 0.8 | N3: 8.9 | O3: 26.6 | P3: 30.2 | Q3: 22.9 | R3: 3.6 | S3: 2.16
A4: {=INDEX(IDs!A:A, MATCH(B4, IDs!B:B, 0))} -> 3 | B4: Abadou | C4: 33.6 | D4: 43.4 | E4: 22.3 | F4: 60.3 | G4: 55.1 | H4: 66.3 | I4: 1.1 | J4: 0.8 | K4: 1.5 | L4: 5 | M4: 0.8 | N4: 9.8 | O4: 29.2 | P4: 33.1 | Q4: 23.9 | R4: 3.8 | S4: 2.23
A5: {=INDEX(IDs!A:A, MATCH(B5, IDs!B:B, 0))} -> 4 | B5: Abaynou | C5: 29.6 | D5: 36.9 | E5: 22.5 | F5: 61.8 | G5: 60.7 | H5: 62.8 | I5: 2.7 | J5: 1.7 | K5: 3.8 | L5: 5.9 | M5: 0.7 | N5: 11 | O5: 28.5 | P5: 31.8 | Q5: 25.9 | R5: 3.1 | S5: 2.64
A6: {=INDEX(IDs!A:A, MATCH(B6, IDs!B:B, 0))} -> 5 | B6: Abbou Lakhal | C6: 29.6 | D6: 38.3 | E6: 20.5 | F6: 65.8 | G6: 61.1 | H6: 70.6 | I6: 0.6 | J6: 0.2 | K6: 1.1 | L6: 4 | M6: 0.4 | N6: 7.8 | O6: 24.5 | P6: 28.1 | Q6: 20.6 | R6: 5.6 | S6: 2.87
A7: {=INDEX(IDs!A:A, MATCH(B7, IDs!B:B, 0))} -> 6 | B7: Abdelghaya Souahel | C7: 37.1 | D7: 46.9 | E7: 25.4 | F7: 57.4 | G7: 51.3 | H7: 64.7 | I7: 1.5 | J7: 1 | K7: 2 | L7: 4 | M7: 0.8 | N7: 7.9 | O7: 29.8 | P7: 35.2 | Q7: 22.3 | R7: 4 | S7: 2.79
A8: {=INDEX(IDs!A:A, MATCH(B8, IDs!B:B, 0))} -> 7 | B8: Abteh | C8: 46.9 | D8: 49 | E8: 44.9 | F8: 48 | G8: 49 | H8: 46.9 | I8: 0.8 | J8: 1.2 | K8: 0.4 | L8: 4.3 | M8: 0.8 | N8: 7.8 | O8: 33 | P8: 36.7 | Q8: 28.1 | R8: 2.5 | S8: 1.67
A9: {=INDEX(IDs!A:A, MATCH(B9, IDs!B:B, 0))} -> 8 | B9: Adaghas | C9: 27.9 | D9: 33.7 | E9: 22.3 | F9: 62.7 | G9: 63.1 | H9: 62.4 | I9: 1.2 | J9: 1 | K9: 1.5 | L9: 8.1 | M9: 2.2 | N9: 13.8 | O9: 30.1 | P9: 33.1 | Q9: 26.3 | R9: 4.6 | S9: 2.6
A10: {=INDEX(IDs!A:A, MATCH(B10, IDs!B:B, 0))} -> 9 | B10: Adar | C10: 31.4 | D10: 28 | E10: 33.2 | F10: 54 | G10: 68.2 | H10: 46.6 | I10: 2 | J10: 1.1 | K10: 2.5 | L10: 12.6 | M10: 2.8 | N10: 17.7 | O10: 34.5 | P10: 35.8 | Q10: 33.8 | R10: 2.3 | S10: 0.98
A11: {=INDEX(IDs!A:A, MATCH(B11, IDs!B:B, 0))} -> 10 | B11: Adassil | C11: 29.5 | D11: 38 | E11: 20.2 | F11: 63.3 | G11: 60 | H11: 66.9 | I11: 1.1 | J11: 0.7 | K11: 1.5 | L11: 6.1 | M11: 1.2 | N11: 11.4 | O11: 26.9 | P11: 30.3 | Q11: 22 | R11: 4.7 | S11: 3.37
A12: {=INDEX(IDs!A:A, MATCH(B12, IDs!B:B, 0))} -> 11 | B12: Aday | C12: 31.7 | D12: 38.3 | E12: 26.5 | F12: 57.2 | G12: 59.1 | H12: 55.7 | I12: 3 | J12: 1.6 | K12: 4.2 | L12: 8 | M12: 1.1 | N12: 13.7 | O12: 32 | P12: 34.7 | Q12: 29.4 | R12: 3 | S12: 1.58
A13: {=INDEX(IDs!A:A, MATCH(B13, IDs!B:B, 0))} -> 12 | B13: Adis | C13: 40.6 | D13: 45.8 | E13: 36.3 | F13: 50.2 | G13: 52.5 | H13: 48.2 | I13: 2.4 | J13: 0.9 | K13: 3.6 | L13: 6.9 | M13: 0.8 | N13: 11.9 | O13: 33.1 | P13: 35.8 | Q13: 30.5 | R13: 2.8 | S13: 1.75
... A34: {=INDEX(IDs!A:A, MATCH(B34, IDs!B:B, 0))} -> 33 | B34: Aghouatim | C34: 30.7 | D34: 38.3 | E34: 22.4 | F34: 63.1 | G34: 59.5 | H34: 67.2 | I34: 1.5 | J34: 1.1 | K34: 2 | L34: 4.6 | M34: 1.1 | N34: 8.5 | O34: 26.7 | P34: 30.8 | Q34: 21.8 | R34: 3.3 | S34: 2.44
A35: {=INDEX(IDs!A:A, MATCH(B35, IDs!B:B, 0))} -> 34 | B35: Aghouinite-N/A | C35: N/A | D35: N/A | E35: N/A | F35: N/A | G35: N/A | H35: N/A | I35: N/A | J35: N/A | K35: N/A | L35: N/A | M35: N/A | N35: N/A | O35: N/A | P35: N/A | Q35: N/A | R35: N/A | S35: N/A
A36: {=INDEX(IDs!A:A, MATCH(B36, IDs!B:B, 0))} -> 35 | B36: Aglif | C36: 23.9 | D36: 29.2 | E36: 19.3 | F36: 66.4 | G36: 69 | H36: 64 | I36: 1.6 | J36: 0.9 | K36: 2.2 | L36: 8.1 | M36: 0.9 | N36: 14.5 | O36: 27 | P36: 30.2 | Q36: 24.1 | R36: 4.8 | S36: 2.45
A37: {=INDEX(IDs!A:A, MATCH(B37, IDs!B:B, 0))} -> 36 | B37: Agoudi N'lkhair | C37: 30.3 | D37: 38.2 | E37: 21.7 | F37: 63.1 | G37: 59.4 | H37: 67.1 | I37: 2 | J37: 1.3 | K37: 2.8 | L37: 4.6 | M37: 1.1 | N37: 8.4 | O37: 27.4 | P37: 31.2 | Q37: 23 | R37: 4.2 | S37: 1.89
A38: {=INDEX(IDs!A:A, MATCH(B38, IDs!B:B, 0))} -> 37 | B38: Agoudim | C38: 28.5 | D38: 36.9 | E38: 19.4 | F38: 62.5 | G38: 59.6 | H38: 65.6 | I38: 3.3 | J38: 2.3 | K38: 4.4 | L38: 5.7 | M38: 1.2 | N38: 10.6 | O38: 27.7 | P38: 31.9 | Q38: 22.9 | R38: 4.4 | S38: 2.56
A39: {=INDEX(IDs!A:A, MATCH(B39, IDs!B:B, 0))} -> 38 | B39: Agourai | C39: 29.8 | D39: 37.2 | E39: 22.9 | F39: 61 | G39: 59.9 | H39: 62 | I39: 4.3 | J39: 2.2 | K39: 6.2 | L39: 4.9 | M39: 0.7 | N39: 8.9 | O39: 27.6 | P39: 32 | Q39: 23.2 | R39: 2.9 | S39: 2.22
A40: {=INDEX(IDs!A:A, MATCH(B40, IDs!B:B, 0))} -> 39 | B40: Aguelmam Azegza | C40: 26.8 | D40: 34.3 | E40: 18.9 | F40: 65.3 | G40: 62.2 | H40: 68.7 | I40: 2.3 | J40: 2.4 | K40: 2.3 | L40: 5.5 | M40: 1.2 | N40: 10.1 | O40: 28.1 | P40: 31.9 | Q40: 23.9 | R40: 3.1 | S40: 2.1
A41: {=INDEX(IDs!A:A, MATCH(B41, IDs!B:B, 0))} -> 40 | B41: Aguelmous | C41: 28.9 | D41: 36.2 | E41: 21.5 | F41: 62.1 | G41: 60.8 | H41: 63.5 | I41: 3.7 | J41: 2 | K41: 5.5 | L41: 5.3 | M41: 1 | N41: 9.5 | O41: 28.6 | P41: 32.3 | Q41: 24.7 | R41: 2.9 | S41: 2.09
A42: {=INDEX(IDs!A:A, MATCH(B42, IDs!B:B, 0))} -> 41 | B42: Aguerd | C42: 27.5 | D42: 34.4 | E42: 20.5 | F42: 63.5 | G42: 62.2 | H42: 64.8 | I42: 2.4 | J42: 1.8 | K42: 3 | L42: 6.6 | M42: 1.5 | N42: 11.7 | O42: 27.6 | P42: 31.7 | Q42: 23.3 | R42: 3 | S42: 2.13
A43: {=INDEX(IDs!A:A, MATCH(B43, IDs!B:B, 0))} -> 42 | B43: Aguinane | C43: 26.9 | D43: 28.1 | E43: 26.1 | F43: 63.9 | G43: 69.8 | H43: 59.3 | I43: 2 | J43: 1.2 | K43: 2.5 | L43: 7.1 | M43: 0.9 | N43: 12.1 | O43: 30.7 | P43: 33.2 | Q43: 29.2 | R43: 3.6 | S43: 2.45
A44: {=INDEX(IDs!A:A, MATCH(B44, IDs!B:B, 0))} -> 43 | B44: Ahdil | C44: 32.3 | D44: 42.2 | E44: 20.1 | F44: 61.4 | G44: 55.4 | H44: 68.8 | I44: 1 | J44: 1.1 | K44: 0.9 | L44: 5.3 | M44: 1.3 | N44: 10.2 | O44: 28.4 | P44: 32.5 | Q44: 22.7 | R44: 4.6 | S44: 2.55
A45: {=INDEX(IDs!A:A, MATCH(B45, IDs!B:B, 0))} -> 44 | B45: Ahfir | C45: 33.9 | D45: 39.1 | E45: 29.4 | F45: 54.9 | G45: 57.9 | H45: 52.3 | I45: 3.9 | J45: 1.9 | K45: 5.6 | L45: 7.3 | M45: 1 | N45: 12.7 | O45: 29.1 | P45: 34.4 | Q45: 24.2 | R45: 2.2 | S45: 1.45
A46: {=INDEX(IDs!A:A, MATCH(B46, IDs!B:B, 0))} -> 45 | B46: Ahl Angad | C46: 32.5 | D46: 39.2 | E46: 25.5 | F46: 61.5 | G46: 58.5 | H46: 64.7 | I46: 2.2 | J46: 1.3 | K46: 3 | L46: 3.8 | M46: 0.9 | N46: 6.8 | O46: 29.3 | P46: 34.3 | Q46: 24.1 | R46: 2.5 | S46: 1.88
A47: {=INDEX(IDs!A:A, MATCH(B47, IDs!B:B, 0))} -> 46 | B47: Ahl Oued Za | C47: 36.8 | D47: 43 | E47: 30.8 | F47: 57.2 | G47: 55.1 | H47: 59.1 | I47: 1.9 | J47: 1.5 | K47: 2.3 | L47: 4.1 | M47: 0.3 | N47: 7.8 | O47: 28.2 | P47: 33.1 | Q47: 23 | R47: 3 | S47: 1.86
... A302: {=INDEX(IDs!A:A, MATCH(B302, IDs!B:B, 0))} -> 301 | B302: Biougra | C302: 32.8 | D302: 38.3 | E302: 27.6 | F302: 59.6 | G302: 59.7 | H302: 59.6 | I302: 3.8 | J302: 1.7 | K302: 5.8 | L302: 3.7 | M302: 0.3 | N302: 7 | O302: 28 | P302: 31.4 | Q302: 24.9 | R302: 2.5 | S302: 1.84
A303: {=INDEX(IDs!A:A, MATCH(B303, IDs!B:B, 0))} -> 302 | B303: Bir Anzarane | C303: 40.7 | D303: 40.9 | E303: 30 | F303: 56.1 | G303: 56.3 | H303: 35 | I303: 3 | J303: 2.8 | K303: 15 | L303: 0.2 | M303: 0 | N303: 20 | O303: 31.2 | P303: 31.2 | R303: 4
A304: {=INDEX(IDs!A:A, MATCH(B304, IDs!B:B, 0))} -> 303 | B304: Bir Ennasr | C304: 29.2 | D304: 37.7 | E304: 19.6 | F304: 65.9 | G304: 61 | H304: 71.4 | I304: 0.9 | J304: 0.6 | K304: 1.3 | L304: 4 | M304: 0.7 | N304: 7.7 | O304: 26.9 | P304: 30.3 | Q304: 22.8 | R304: 4.2 | S304: 2.24
A305: {=INDEX(IDs!A:A, MATCH(B305, IDs!B:B, 0))} -> 304 | B305: Bir Gandouz | C305: 35.9 | D305: 41.4 | E305: 22.1 | F305: 60.2 | G305: 56.2 | H305: 70.2 | I305: 3.1 | J305: 2.2 | K305: 5.4 | L305: 0.8 | M305: 0.2 | N305: 2.3 | O305: 28.7 | P305: 32 | Q305: 21.4 | R305: 3.4 | S305: 2.94
A306: {=INDEX(IDs!A:A, MATCH(B306, IDs!B:B, 0))} -> 305 | B306: Bir Mezoui | C306: 31.1 | D306: 40.6 | E306: 22.4 | F306: 59 | G306: 57.5 | H306: 60.4 | I306: 2.3 | J306: 1.1 | K306: 3.4 | L306: 7.6 | M306: 0.8 | N306: 13.8 | O306: 27.7 | P306: 33.7 | Q306: 21.9 | R306: 3 | S306: 2.5
A307: {=INDEX(IDs!A:A, MATCH(B307, IDs!B:B, 0))} -> 306 | B307: Bir Taleb | C307: 31 | D307: 36.9 | E307: 24.9 | F307: 60.4 | G307: 59.1 | H307: 61.8 | I307: 3.8 | J307: 2.7 | K307: 4.9 | L307: 4.8 | M307: 1.3 | N307: 8.4 | O307: 26.1 | P307: 33 | Q307: 17 | R307: 2.7 | S307: 2.09
A308: {=INDEX(IDs!A:A, MATCH(B308, IDs!B:B, 0))} -> 307 | B308: Bir Tam-Tam | C308: 27.9 | D308: 34.5 | E308: 21.7 | F308: 62.3 | G308: 62 | H308: 62.6 | I308: 3.9 | J308: 2.7 | K308: 5 | L308: 5.8 | M308: 0.7 | N308: 10.7 | O308: 27.5 | P308: 33.4 | Q308: 21.6 | R308: 2.7 | S308: 1.54
A309: {=INDEX(IDs!A:A, MATCH(B309, IDs!B:B, 0))} -> 308 | B309: Bitit | C309: 30.4 | D309: 36.4 | E309: 24.3 | F309: 62.1 | G309: 60.6 | H309: 63.7 | I309: 3 | J309: 2.1 | K309: 3.9 | L309: 4.5 | M309: 1 | N309: 8.1 | O309: 27.9 | P309: 31.8 | Q309: 23.8 | R309: 2.9 | S309: 2.38
A310: {=INDEX(IDs!A:A, MATCH(B310, IDs!B:B, 0))} -> 309 | B310: Bizdad | C310: 24.5 | D310: 29.8 | E310: 19.4 | F310: 67.1 | G310: 68 | H310: 66.2 | I310: 1.3 | J310: 1 | K310: 1.7 | L310: 7.1 | M310: 1.2 | N310: 12.6 | O310: 26.8 | P310: 30.6 | Q310: 22.9 | R310: 4.1 | S310: 2.69
A311: {=INDEX(IDs!A:A, MATCH(B311, IDs!B:B, 0))} -> 310 | B311: Bleida | C311: 34.5 | D311: 39.8 | E311: 29 | F311: 62.1 | G311: 59.5 | H311: 64.8 | I311: 0.7 | J311: 0.3 | K311: 1.1 | L311: 2.7 | M311: 0.4 | N311: 5.1 | O311: 27.7 | P311: 29.5 | Q311: 25.6 | R311: 4.2 | S311: 3.12
A312: {=INDEX(IDs!A:A, MATCH(B312, IDs!B:B, 0))} -> 311 | B312: Bni A'yat | C312: 28.6 | D312: 36.3 | E312: 21.8 | F312: 60.9 | G312: 60.4 | H312: 61.3 | I312: 2.8 | J312: 2.1 | K312: 3.5 | L312: 7.8 | M312: 1.3 | N312: 13.5 | O312: 27 | P312: 33.3 | Q312: 21.9 | R312: 3.1 | S312: 1.99
A313: {=INDEX(IDs!A:A, MATCH(B313, IDs!B:B, 0))} -> 312 | B313: Bni Abdellah | C313: 41.6 | D313: 44.9 | E313: 38.7 | F313: 51.7 | G313: 53.3 | H313: 50.2 | I313: 1.6 | J313: 0.9 | K313: 2.1 | L313: 5.2 | M313: 0.9 | N313: 8.9 | O313: 31.8 | P313: 37.2 | Q313: 26 | R313: 2 | S313: 1.81
A314: {=INDEX(IDs!A:A, MATCH(B314, IDs!B:B, 0))} -> 313 | B314: Bni Ahmed Cherqia | C314: 31 | D314: 39.2 | E314: 22.1 | F314: 61.4 | G314: 58.2 | H314: 64.9 | I314: 2.7 | J314: 2 | K314: 3.5 | L314: 4.9 | M314: 0.6 | N314: 9.6 | O314: 28.2 | P314: 32.6 | Q314: 23.8 | R314: 3.1 | S314: 1.78
...

Sheet Sheet7
A1: Libelle Arabe | B1: Libelle Français | C1: Age Moyen au Premier mariage (Année): Féminins
A2: اعرب صباح اغريس | B2: Aarab Sebbah Gheris | C2: 22.8
A3: عرب صباح زيز | B3: Aarab Sebbah Ziz | C3: 22.9
A4: أبادو | B4: Abadou | C4: 23.9
A5: أباينو | B5: Abaynou | C5: 25.9
A6: عبو لكحل | B6: Abbou Lakhal | C6: 20.6
A7: عبد الغاية السواحل | B7: Abdelghaya Souahel | C7: 22.3
A8: أبطيح | B8: Abteh | C8: 28.1
A9: أدغاس | B9: Adaghas | C9: 26.3
A10: أضار | B10: Adar | C10: 33.8
A11: اداسيل | B11: Adassil | C11: 22
A12: أداي | B12: Aday | C12: 29.4
A13: اديس | B13: Adis | C13: 30.5
... A34: اغواطيم | B34: Aghouatim | C34: 21.8
A35: اغوينيت | B35: Aghouinite
A36: اكليف | B36: Aglif | C36: 24.1
A37: أكودي نلخير | B37: Agoudi N'lkhair | C37: 23
A38: أكديم | B38: Agoudim | C38: 22.9
A39: أكوراي | B39: Agourai | C39: 23.2
A40: أكلمام أزكزا | B40: Aguelmam Azegza | C40: 23.9
A41: أكلموس | B41: Aguelmous | C41: 24.7
A42: اكرض | B42: Aguerd | C42: 23.3
A43: أكينان | B43: Aguinane | C43: 29.2
A44: اهديل | B44: Ahdil | C44: 22.7
A45: أحفير | B45: Ahfir | C45: 24.2
A46: أهل انكاد | B46: Ahl Angad | C46: 24.1
A47: أهل وادزا | B47: Ahl Oued Za | C47: 23
... A302: بيوكرى | B302: Biougra | C302: 24.9
A303: بئر أنزران | B303: Bir Anzarane
A304: بئر النصر | B304: Bir Ennasr | C304: 22.8
A305: بئر كندوز | B305: Bir Gandouz | C305: 21.4
A306: بئر مزوي | B306: Bir Mezoui | C306: 21.9
A307: بير الطالب | B307: Bir Taleb | C307: 17
A308: بئر طم طم | B308: Bir Tam-Tam | C308: 21.6
A309: بطيط | B309: Bitit | C309: 23.8
A310: بيزضاض | B310: Bizdad | C310: 22.9
A311: ابليدة | B311: Bleida | C311: 25.6
A312: بني عياط | B312: Bni A'yat | C312: 21.9
A313: بني عبد الله | B313: Bni Abdellah | C313: 26
A314: بني احمد الشرقية | B314: Bni Ahmed Cherqia | C314: 23.8
...
